        
Flaky-test: org.apache.pulsar.broker.service.BacklogQuotaManagerTest.testConsumerBacklogEvictionTimeQuotaWithEmptyLedger
Number of failures: 1

org.apache.pulsar.broker.service.BacklogQuotaManagerTest is flaky. The testConsumerBacklogEvictionTimeQuotaWithEmptyLedger test method fails sporadically.

```
org.awaitility.core.ConditionTimeoutException: Assertion condition defined as a org.apache.pulsar.broker.service.BacklogQuotaManagerTest expected [0] but found [1] within 2 seconds.
	at org.awaitility.core.ConditionAwaiter.await(ConditionAwaiter.java:167)
	at org.awaitility.core.AssertionCondition.await(AssertionCondition.java:119)
	at org.awaitility.core.AssertionCondition.await(AssertionCondition.java:31)
	at org.awaitility.core.ConditionFactory.until(ConditionFactory.java:985)
	at org.awaitility.core.ConditionFactory.untilAsserted(ConditionFactory.java:769)
	at org.apache.pulsar.broker.service.BacklogQuotaManagerTest.testConsumerBacklogEvictionTimeQuotaWithEmptyLedger(BacklogQuotaManagerTest.java:557)
```

Usage tip: To enable automatic navigation to failure message, open the following links with CTRL/CMD-click.  
[example failure 2022-07-19T01:53:22.6480785Z](https://github.com/apache/pulsar/runs/7401074390?check_suite_focus=true#step:9:715)  


<details>
<summary>Full exception stacktrace</summary>
<code><pre>
org.awaitility.core.ConditionTimeoutException: Assertion condition defined as a org.apache.pulsar.broker.service.BacklogQuotaManagerTest expected [0] but found [1] within 2 seconds.
	at org.awaitility.core.ConditionAwaiter.await(ConditionAwaiter.java:167)
	at org.awaitility.core.AssertionCondition.await(AssertionCondition.java:119)
	at org.awaitility.core.AssertionCondition.await(AssertionCondition.java:31)
	at org.awaitility.core.ConditionFactory.until(ConditionFactory.java:985)
	at org.awaitility.core.ConditionFactory.untilAsserted(ConditionFactory.java:769)
	at org.apache.pulsar.broker.service.BacklogQuotaManagerTest.testConsumerBacklogEvictionTimeQuotaWithEmptyLedger(BacklogQuotaManagerTest.java:557)
	at java.base/jdk.internal.reflect.NativeMethodAccessorImpl.invoke0(Native Method)
	at java.base/jdk.internal.reflect.NativeMethodAccessorImpl.invoke(NativeMethodAccessorImpl.java:77)
	at java.base/jdk.internal.reflect.DelegatingMethodAccessorImpl.invoke(DelegatingMethodAccessorImpl.java:43)
	at java.base/java.lang.reflect.Method.invoke(Method.java:568)
	at org.testng.internal.MethodInvocationHelper.invokeMethod(MethodInvocationHelper.java:132)
	at org.testng.internal.InvokeMethodRunnable.runOne(InvokeMethodRunnable.java:45)
	at org.testng.internal.InvokeMethodRunnable.call(InvokeMethodRunnable.java:73)
	at org.testng.internal.InvokeMethodRunnable.call(InvokeMethodRunnable.java:11)
	at java.base/java.util.concurrent.FutureTask.run(FutureTask.java:264)
	at java.base/java.util.concurrent.ThreadPoolExecutor.runWorker(ThreadPoolExecutor.java:1136)
	at java.base/java.util.concurrent.ThreadPoolExecutor$Worker.run(ThreadPoolExecutor.java:635)
	at java.base/java.lang.Thread.run(Thread.java:833)
Caused by: java.lang.AssertionError: expected [0] but found [1]
	at org.testng.Assert.fail(Assert.java:99)
	at org.testng.Assert.failNotEquals(Assert.java:1037)
	at org.testng.Assert.assertEqualsImpl(Assert.java:140)
	at org.testng.Assert.assertEquals(Assert.java:122)
	at org.testng.Assert.assertEquals(Assert.java:797)
	at org.testng.Assert.assertEquals(Assert.java:807)
	at org.apache.pulsar.broker.service.BacklogQuotaManagerTest.lambda$testConsumerBacklogEvictionTimeQuotaWithEmptyLedger$5(BacklogQuotaManagerTest.java:566)
	at org.awaitility.core.AssertionCondition.lambda$new$0(AssertionCondition.java:53)
	at org.awaitility.core.ConditionAwaiter$ConditionPoller.call(ConditionAwaiter.java:248)
	at org.awaitility.core.ConditionAwaiter$ConditionPoller.call(ConditionAwaiter.java:235)
	... 4 more

</pre></code>
</details>

