        
Flaky-test: org.apache.pulsar.metadata.ZKSessionTest.testReacquireLeadershipAfterSessionLost
Number of failures: 4

org.apache.pulsar.metadata.ZKSessionTest is flaky. The testReacquireLeadershipAfterSessionLost test method fails sporadically.

```
org.awaitility.core.ConditionTimeoutException: Assertion condition defined as a lambda expression in org.apache.pulsar.metadata.ZKSessionTest that uses org.apache.pulsar.metadata.api.coordination.LeaderElection expected [Leading] but found [NoLeader] within 10 seconds.
	at org.awaitility.core.ConditionAwaiter.await(ConditionAwaiter.java:165)
	at org.awaitility.core.AssertionCondition.await(AssertionCondition.java:119)
	at org.awaitility.core.AssertionCondition.await(AssertionCondition.java:31)
	at org.awaitility.core.ConditionFactory.until(ConditionFactory.java:895)
	at org.awaitility.core.ConditionFactory.untilAsserted(ConditionFactory.java:679)
	at org.apache.pulsar.metadata.ZKSessionTest.testReacquireLeadershipAfterSessionLost(ZKSessionTest.java:174)
```

Usage tip: To enable automatic navigation to failure message, open the following links with CTRL/CMD-click.
[example failure 2021-08-25T09:02:04.0248139Z](https://github.com/apache/pulsar/runs/3420085646?check_suite_focus=true#step:9:1550)


<details>
<summary>Full exception stacktrace</summary>
<code><pre>
org.awaitility.core.ConditionTimeoutException: Assertion condition defined as a lambda expression in org.apache.pulsar.metadata.ZKSessionTest that uses org.apache.pulsar.metadata.api.coordination.LeaderElection expected [Leading] but found [NoLeader] within 10 seconds.
	at org.awaitility.core.ConditionAwaiter.await(ConditionAwaiter.java:165)
	at org.awaitility.core.AssertionCondition.await(AssertionCondition.java:119)
	at org.awaitility.core.AssertionCondition.await(AssertionCondition.java:31)
	at org.awaitility.core.ConditionFactory.until(ConditionFactory.java:895)
	at org.awaitility.core.ConditionFactory.untilAsserted(ConditionFactory.java:679)
	at org.apache.pulsar.metadata.ZKSessionTest.testReacquireLeadershipAfterSessionLost(ZKSessionTest.java:174)
	at java.base/jdk.internal.reflect.NativeMethodAccessorImpl.invoke0(Native Method)
	at java.base/jdk.internal.reflect.NativeMethodAccessorImpl.invoke(NativeMethodAccessorImpl.java:62)
	at java.base/jdk.internal.reflect.DelegatingMethodAccessorImpl.invoke(DelegatingMethodAccessorImpl.java:43)
	at java.base/java.lang.reflect.Method.invoke(Method.java:566)
	at org.testng.internal.MethodInvocationHelper.invokeMethod(MethodInvocationHelper.java:132)
	at org.testng.internal.InvokeMethodRunnable.runOne(InvokeMethodRunnable.java:45)
	at org.testng.internal.InvokeMethodRunnable.call(InvokeMethodRunnable.java:73)
	at org.testng.internal.InvokeMethodRunnable.call(InvokeMethodRunnable.java:11)
	at java.base/java.util.concurrent.FutureTask.run(FutureTask.java:264)
	at java.base/java.util.concurrent.ThreadPoolExecutor.runWorker(ThreadPoolExecutor.java:1128)
	at java.base/java.util.concurrent.ThreadPoolExecutor$Worker.run(ThreadPoolExecutor.java:628)
	at java.base/java.lang.Thread.run(Thread.java:829)
Caused by: java.lang.AssertionError: expected [Leading] but found [NoLeader]
	at org.testng.Assert.fail(Assert.java:99)
	at org.testng.Assert.failNotEquals(Assert.java:1037)
	at org.testng.Assert.assertEqualsImpl(Assert.java:140)
	at org.testng.Assert.assertEquals(Assert.java:122)
	at org.testng.Assert.assertEquals(Assert.java:617)
	at org.apache.pulsar.metadata.ZKSessionTest.lambda$testReacquireLeadershipAfterSessionLost$1(ZKSessionTest.java:175)
	at org.awaitility.core.AssertionCondition.lambda$new$0(AssertionCondition.java:53)
	at org.awaitility.core.ConditionAwaiter$ConditionPoller.call(ConditionAwaiter.java:222)
	at org.awaitility.core.ConditionAwaiter$ConditionPoller.call(ConditionAwaiter.java:209)
	... 4 more

</pre></code>
</details>

```
org.awaitility.core.ConditionTimeoutException: Assertion condition defined as a lambda expression in org.apache.pulsar.metadata.ZKSessionTest that uses org.apache.pulsar.metadata.api.coordination.LeaderElection expected [Leading] but found [NoLeader] within 10 seconds.
	at org.awaitility.core.ConditionAwaiter.await(ConditionAwaiter.java:165)
	at org.awaitility.core.AssertionCondition.await(AssertionCondition.java:119)
	at org.awaitility.core.AssertionCondition.await(AssertionCondition.java:31)
	at org.awaitility.core.ConditionFactory.until(ConditionFactory.java:895)
	at org.awaitility.core.ConditionFactory.untilAsserted(ConditionFactory.java:679)
	at org.apache.pulsar.metadata.ZKSessionTest.testReacquireLeadershipAfterSessionLost(ZKSessionTest.java:172)
```

Usage tip: To enable automatic navigation to failure message, open the following links with CTRL/CMD-click.
[example failure 2021-08-30T14:38:41.1002016Z](https://github.com/apache/pulsar/runs/3462898842?check_suite_focus=true#step:8:1456)


<details>
<summary>Full exception stacktrace</summary>
<code><pre>
org.awaitility.core.ConditionTimeoutException: Assertion condition defined as a lambda expression in org.apache.pulsar.metadata.ZKSessionTest that uses org.apache.pulsar.metadata.api.coordination.LeaderElection expected [Leading] but found [NoLeader] within 10 seconds.
	at org.awaitility.core.ConditionAwaiter.await(ConditionAwaiter.java:165)
	at org.awaitility.core.AssertionCondition.await(AssertionCondition.java:119)
	at org.awaitility.core.AssertionCondition.await(AssertionCondition.java:31)
	at org.awaitility.core.ConditionFactory.until(ConditionFactory.java:895)
	at org.awaitility.core.ConditionFactory.untilAsserted(ConditionFactory.java:679)
	at org.apache.pulsar.metadata.ZKSessionTest.testReacquireLeadershipAfterSessionLost(ZKSessionTest.java:172)
	at java.base/jdk.internal.reflect.NativeMethodAccessorImpl.invoke0(Native Method)
	at java.base/jdk.internal.reflect.NativeMethodAccessorImpl.invoke(NativeMethodAccessorImpl.java:62)
	at java.base/jdk.internal.reflect.DelegatingMethodAccessorImpl.invoke(DelegatingMethodAccessorImpl.java:43)
	at java.base/java.lang.reflect.Method.invoke(Method.java:566)
	at org.testng.internal.MethodInvocationHelper.invokeMethod(MethodInvocationHelper.java:132)
	at org.testng.internal.InvokeMethodRunnable.runOne(InvokeMethodRunnable.java:45)
	at org.testng.internal.InvokeMethodRunnable.call(InvokeMethodRunnable.java:73)
	at org.testng.internal.InvokeMethodRunnable.call(InvokeMethodRunnable.java:11)
	at java.base/java.util.concurrent.FutureTask.run(FutureTask.java:264)
	at java.base/java.util.concurrent.ThreadPoolExecutor.runWorker(ThreadPoolExecutor.java:1128)
	at java.base/java.util.concurrent.ThreadPoolExecutor$Worker.run(ThreadPoolExecutor.java:628)
	at java.base/java.lang.Thread.run(Thread.java:829)
Caused by: java.lang.AssertionError: expected [Leading] but found [NoLeader]
	at org.testng.Assert.fail(Assert.java:99)
	at org.testng.Assert.failNotEquals(Assert.java:1037)
	at org.testng.Assert.assertEqualsImpl(Assert.java:140)
	at org.testng.Assert.assertEquals(Assert.java:122)
	at org.testng.Assert.assertEquals(Assert.java:617)
	at org.apache.pulsar.metadata.ZKSessionTest.lambda$testReacquireLeadershipAfterSessionLost$1(ZKSessionTest.java:172)
	at org.awaitility.core.AssertionCondition.lambda$new$0(AssertionCondition.java:53)
	at org.awaitility.core.ConditionAwaiter$ConditionPoller.call(ConditionAwaiter.java:222)
	at org.awaitility.core.ConditionAwaiter$ConditionPoller.call(ConditionAwaiter.java:209)
	... 4 more

</pre></code>
</details>

```
java.util.concurrent.CompletionException: org.apache.pulsar.metadata.api.MetadataStoreException$NotFoundException: org.apache.zookeeper.KeeperException$NoNodeException: KeeperErrorCode = NoNode for /key-559075228174
	at java.base/java.util.concurrent.CompletableFuture.encodeThrowable(CompletableFuture.java:331)
	at java.base/java.util.concurrent.CompletableFuture.completeThrowable(CompletableFuture.java:346)
	at java.base/java.util.concurrent.CompletableFuture$UniRun.tryFire(CompletableFuture.java:777)
	at java.base/java.util.concurrent.CompletableFuture.postComplete(CompletableFuture.java:506)
	at java.base/java.util.concurrent.CompletableFuture.completeExceptionally(CompletableFuture.java:2088)
	at org.apache.pulsar.metadata.impl.ZKMetadataStore.lambda$storeDelete$22(ZKMetadataStore.java:308)
	at java.base/java.util.concurrent.ThreadPoolExecutor.runWorker(ThreadPoolExecutor.java:1128)
	at java.base/java.util.concurrent.ThreadPoolExecutor$Worker.run(ThreadPoolExecutor.java:628)
	at io.netty.util.concurrent.FastThreadLocalRunnable.run(FastThreadLocalRunnable.java:30)
	at java.base/java.lang.Thread.run(Thread.java:829)
Caused by: org.apache.pulsar.metadata.api.MetadataStoreException$NotFoundException: org.apache.zookeeper.KeeperException$NoNodeException: KeeperErrorCode = NoNode for /key-559075228174
	at org.apache.pulsar.metadata.impl.ZKMetadataStore.getException(ZKMetadataStore.java:341)
	... 5 more
Caused by: org.apache.zookeeper.KeeperException$NoNodeException: KeeperErrorCode = NoNode for /key-559075228174
```

Usage tip: To enable automatic navigation to failure message, open the following links with CTRL/CMD-click.
[example failure 2021-08-30T14:44:19.0567535Z](https://github.com/apache/pulsar/runs/3462898842?check_suite_focus=true#step:8:4764)


<details>
<summary>Full exception stacktrace</summary>
<code><pre>
java.util.concurrent.CompletionException: org.apache.pulsar.metadata.api.MetadataStoreException$NotFoundException: org.apache.zookeeper.KeeperException$NoNodeException: KeeperErrorCode = NoNode for /key-559075228174
	at java.base/java.util.concurrent.CompletableFuture.encodeThrowable(CompletableFuture.java:331)
	at java.base/java.util.concurrent.CompletableFuture.completeThrowable(CompletableFuture.java:346)
	at java.base/java.util.concurrent.CompletableFuture$UniRun.tryFire(CompletableFuture.java:777)
	at java.base/java.util.concurrent.CompletableFuture.postComplete(CompletableFuture.java:506)
	at java.base/java.util.concurrent.CompletableFuture.completeExceptionally(CompletableFuture.java:2088)
	at org.apache.pulsar.metadata.impl.ZKMetadataStore.lambda$storeDelete$22(ZKMetadataStore.java:308)
	at java.base/java.util.concurrent.ThreadPoolExecutor.runWorker(ThreadPoolExecutor.java:1128)
	at java.base/java.util.concurrent.ThreadPoolExecutor$Worker.run(ThreadPoolExecutor.java:628)
	at io.netty.util.concurrent.FastThreadLocalRunnable.run(FastThreadLocalRunnable.java:30)
	at java.base/java.lang.Thread.run(Thread.java:829)
Caused by: org.apache.pulsar.metadata.api.MetadataStoreException$NotFoundException: org.apache.zookeeper.KeeperException$NoNodeException: KeeperErrorCode = NoNode for /key-559075228174
	at org.apache.pulsar.metadata.impl.ZKMetadataStore.getException(ZKMetadataStore.java:341)
	... 5 more
Caused by: org.apache.zookeeper.KeeperException$NoNodeException: KeeperErrorCode = NoNode for /key-559075228174
	at org.apache.zookeeper.KeeperException.create(KeeperException.java:118)
	at org.apache.zookeeper.KeeperException.create(KeeperException.java:54)
	at org.apache.pulsar.metadata.impl.ZKMetadataStore.getException(ZKMetadataStore.java:335)
	... 5 more

</pre></code>
</details>

```
java.util.concurrent.CompletionException: org.apache.pulsar.metadata.api.MetadataStoreException: org.apache.zookeeper.KeeperException$ConnectionLossException: KeeperErrorCode = ConnectionLoss for /key-1484361384955
	at java.base/java.util.concurrent.CompletableFuture.encodeThrowable(CompletableFuture.java:331)
	at java.base/java.util.concurrent.CompletableFuture.completeThrowable(CompletableFuture.java:346)
	at java.base/java.util.concurrent.CompletableFuture$UniRun.tryFire(CompletableFuture.java:777)
	at java.base/java.util.concurrent.CompletableFuture.postComplete(CompletableFuture.java:506)
	at java.base/java.util.concurrent.CompletableFuture.completeExceptionally(CompletableFuture.java:2088)
	at org.apache.pulsar.metadata.impl.ZKMetadataStore.lambda$storeDelete$22(ZKMetadataStore.java:308)
	at java.base/java.util.concurrent.ThreadPoolExecutor.runWorker(ThreadPoolExecutor.java:1128)
	at java.base/java.util.concurrent.ThreadPoolExecutor$Worker.run(ThreadPoolExecutor.java:628)
	at io.netty.util.concurrent.FastThreadLocalRunnable.run(FastThreadLocalRunnable.java:30)
	at java.base/java.lang.Thread.run(Thread.java:829)
Caused by: org.apache.pulsar.metadata.api.MetadataStoreException: org.apache.zookeeper.KeeperException$ConnectionLossException: KeeperErrorCode = ConnectionLoss for /key-1484361384955
	at org.apache.pulsar.metadata.impl.ZKMetadataStore.getException(ZKMetadataStore.java:345)
	... 5 more
Caused by: org.apache.zookeeper.KeeperException$ConnectionLossException: KeeperErrorCode = ConnectionLoss for /key-1484361384955
```

Usage tip: To enable automatic navigation to failure message, open the following links with CTRL/CMD-click.
[example failure 2021-08-28T00:06:58.4769420Z](https://github.com/apache/pulsar/runs/3447917397?check_suite_focus=true#step:8:8461)


<details>
<summary>Full exception stacktrace</summary>
<code><pre>
java.util.concurrent.CompletionException: org.apache.pulsar.metadata.api.MetadataStoreException: org.apache.zookeeper.KeeperException$ConnectionLossException: KeeperErrorCode = ConnectionLoss for /key-1484361384955
	at java.base/java.util.concurrent.CompletableFuture.encodeThrowable(CompletableFuture.java:331)
	at java.base/java.util.concurrent.CompletableFuture.completeThrowable(CompletableFuture.java:346)
	at java.base/java.util.concurrent.CompletableFuture$UniRun.tryFire(CompletableFuture.java:777)
	at java.base/java.util.concurrent.CompletableFuture.postComplete(CompletableFuture.java:506)
	at java.base/java.util.concurrent.CompletableFuture.completeExceptionally(CompletableFuture.java:2088)
	at org.apache.pulsar.metadata.impl.ZKMetadataStore.lambda$storeDelete$22(ZKMetadataStore.java:308)
	at java.base/java.util.concurrent.ThreadPoolExecutor.runWorker(ThreadPoolExecutor.java:1128)
	at java.base/java.util.concurrent.ThreadPoolExecutor$Worker.run(ThreadPoolExecutor.java:628)
	at io.netty.util.concurrent.FastThreadLocalRunnable.run(FastThreadLocalRunnable.java:30)
	at java.base/java.lang.Thread.run(Thread.java:829)
Caused by: org.apache.pulsar.metadata.api.MetadataStoreException: org.apache.zookeeper.KeeperException$ConnectionLossException: KeeperErrorCode = ConnectionLoss for /key-1484361384955
	at org.apache.pulsar.metadata.impl.ZKMetadataStore.getException(ZKMetadataStore.java:345)
	... 5 more
Caused by: org.apache.zookeeper.KeeperException$ConnectionLossException: KeeperErrorCode = ConnectionLoss for /key-1484361384955
	at org.apache.zookeeper.KeeperException.create(KeeperException.java:102)
	at org.apache.zookeeper.KeeperException.create(KeeperException.java:54)
	at org.apache.pulsar.metadata.impl.ZKMetadataStore.getException(ZKMetadataStore.java:335)
	... 5 more

</pre></code>
</details>

